Traceback (most recent call last):
  File "/opt/hostedtoolcache/Python/3.7.12/x64/lib/python3.7/site-packages/jupyter_cache/executors/utils.py", line 56, in single_nb_execution
    record_timing=False,
  File "/opt/hostedtoolcache/Python/3.7.12/x64/lib/python3.7/site-packages/nbclient/client.py", line 1117, in execute
    return NotebookClient(nb=nb, resources=resources, km=km, **kwargs).execute()
  File "/opt/hostedtoolcache/Python/3.7.12/x64/lib/python3.7/site-packages/nbclient/util.py", line 78, in wrapped
    return just_run(coro(*args, **kwargs))
  File "/opt/hostedtoolcache/Python/3.7.12/x64/lib/python3.7/site-packages/nbclient/util.py", line 57, in just_run
    return loop.run_until_complete(coro)
  File "/opt/hostedtoolcache/Python/3.7.12/x64/lib/python3.7/asyncio/base_events.py", line 587, in run_until_complete
    return future.result()
  File "/opt/hostedtoolcache/Python/3.7.12/x64/lib/python3.7/site-packages/nbclient/client.py", line 559, in async_execute
    cell, index, execution_count=self.code_cells_executed + 1
  File "/opt/hostedtoolcache/Python/3.7.12/x64/lib/python3.7/site-packages/nbclient/client.py", line 862, in async_execute_cell
    self._check_raise_for_error(cell, exec_reply)
  File "/opt/hostedtoolcache/Python/3.7.12/x64/lib/python3.7/site-packages/nbclient/client.py", line 765, in _check_raise_for_error
    raise CellExecutionError.from_cell_and_msg(cell, exec_reply_content)
nbclient.exceptions.CellExecutionError: An error occurred while executing the following cell:
------------------
# Fixing random state for reproducibility
np.random.seed(19680801)

N = 10
data = [np.logspace(0, 1, 100) + np.random.randn(100) + ii for ii in range(N)]
data = np.array(data).T
cmap = plt.cm.coolwarm
rcParams['axes.prop_cycle'] = cycler(color=cmap(np.linspace(0, 1, N)))


from matplotlib.lines import Line2D
custom_lines = [Line2D([0], [0], color=cmap(0.), lw=4),
                Line2D([0], [0], color=cmap(.5), lw=4),
                Line2D([0], [0], color=cmap(1.), lw=4)]

fig, ax = plt.subplots(figsize=(10, 5))
lines = ax.plot(data)
ax.legend(custom_lines, ['Cold', 'Medium', 'Hot']);
------------------

[0;31m---------------------------------------------------------------------------[0m
[0;31mNameError[0m                                 Traceback (most recent call last)
[0;32m/tmp/ipykernel_1603/812981093.py[0m in [0;36m<module>[0;34m[0m
[1;32m      5[0m [0mdata[0m [0;34m=[0m [0;34m[[0m[0mnp[0m[0;34m.[0m[0mlogspace[0m[0;34m([0m[0;36m0[0m[0;34m,[0m [0;36m1[0m[0;34m,[0m [0;36m100[0m[0;34m)[0m [0;34m+[0m [0mnp[0m[0;34m.[0m[0mrandom[0m[0;34m.[0m[0mrandn[0m[0;34m([0m[0;36m100[0m[0;34m)[0m [0;34m+[0m [0mii[0m [0;32mfor[0m [0mii[0m [0;32min[0m [0mrange[0m[0;34m([0m[0mN[0m[0;34m)[0m[0;34m][0m[0;34m[0m[0;34m[0m[0m
[1;32m      6[0m [0mdata[0m [0;34m=[0m [0mnp[0m[0;34m.[0m[0marray[0m[0;34m([0m[0mdata[0m[0;34m)[0m[0;34m.[0m[0mT[0m[0;34m[0m[0;34m[0m[0m
[0;32m----> 7[0;31m [0mcmap[0m [0;34m=[0m [0mplt[0m[0;34m.[0m[0mcm[0m[0;34m.[0m[0mcoolwarm[0m[0;34m[0m[0;34m[0m[0m
[0m[1;32m      8[0m [0mrcParams[0m[0;34m[[0m[0;34m'axes.prop_cycle'[0m[0;34m][0m [0;34m=[0m [0mcycler[0m[0;34m([0m[0mcolor[0m[0;34m=[0m[0mcmap[0m[0;34m([0m[0mnp[0m[0;34m.[0m[0mlinspace[0m[0;34m([0m[0;36m0[0m[0;34m,[0m [0;36m1[0m[0;34m,[0m [0mN[0m[0;34m)[0m[0;34m)[0m[0;34m)[0m[0;34m[0m[0;34m[0m[0m
[1;32m      9[0m [0;34m[0m[0m

[0;31mNameError[0m: name 'plt' is not defined
NameError: name 'plt' is not defined

